{
 "cells": [
  {
   "cell_type": "code",
   "execution_count": 4,
   "metadata": {},
   "outputs": [
    {
     "ename": "SyntaxError",
     "evalue": "invalid syntax (rules.py, line 62)",
     "output_type": "error",
     "traceback": [
      "Traceback \u001b[0;36m(most recent call last)\u001b[0m:\n",
      "\u001b[0m  File \u001b[1;32m~/.local/lib/python3.8/site-packages/IPython/core/interactiveshell.py:3460\u001b[0m in \u001b[1;35mrun_code\u001b[0m\n    exec(code_obj, self.user_global_ns, self.user_ns)\u001b[0m\n",
      "\u001b[0m  Cell \u001b[1;32mIn[4], line 6\u001b[0m\n    from pegasus.data import infeed\u001b[0m\n",
      "\u001b[0m  File \u001b[1;32m~/.local/lib/python3.8/site-packages/pegasus/__init__.py:1\u001b[0m\n    from pegasus.parser import *\u001b[0m\n",
      "\u001b[0;36m  File \u001b[0;32m~/.local/lib/python3.8/site-packages/pegasus/parser.py:10\u001b[0;36m\n\u001b[0;31m    from pegasus.rules import _build_rule, ParseError, Lazy\u001b[0;36m\n",
      "\u001b[0;36m  File \u001b[0;32m~/.local/lib/python3.8/site-packages/pegasus/rules.py:62\u001b[0;36m\u001b[0m\n\u001b[0;31m    print 'pegasus: {}\\x1b[2;38;5;241menter {} -> {}\\x1b[m'.format(depth, repr(char()), _name)\u001b[0m\n\u001b[0m          ^\u001b[0m\n\u001b[0;31mSyntaxError\u001b[0m\u001b[0;31m:\u001b[0m invalid syntax\n"
     ]
    }
   ],
   "source": [
    "import itertools\n",
    "import os\n",
    "import time\n",
    "\n",
    "from absl import logging\n",
    "from pegasus.data import infeed\n",
    "from pegasus.params import all_params\n",
    "from pegasus.params import estimator_utils\n",
    "from pegasus.params import registry\n",
    "import tensorflow as tf\n",
    "from pegasus.eval import text_eval\n",
    "from pegasus.ops import public_parsing_ops"
   ]
  },
  {
   "cell_type": "code",
   "execution_count": 5,
   "metadata": {},
   "outputs": [
    {
     "name": "stdout",
     "output_type": "stream",
     "text": [
      "Unexpected exception formatting exception. Falling back to standard exception\n"
     ]
    },
    {
     "name": "stderr",
     "output_type": "stream",
     "text": [
      "Traceback (most recent call last):\n",
      "  File \"/home/osboxes/.local/lib/python3.8/site-packages/IPython/core/interactiveshell.py\", line 3460, in run_code\n",
      "    exec(code_obj, self.user_global_ns, self.user_ns)\n",
      "  File \"/tmp/ipykernel_5449/1908094005.py\", line 1, in <module>\n",
      "    tf.enable_eager_execution()\n",
      "NameError: name 'tf' is not defined\n",
      "\n",
      "During handling of the above exception, another exception occurred:\n",
      "\n",
      "Traceback (most recent call last):\n",
      "  File \"/home/osboxes/.local/lib/python3.8/site-packages/IPython/core/interactiveshell.py\", line 2057, in showtraceback\n",
      "    stb = self.InteractiveTB.structured_traceback(\n",
      "  File \"/home/osboxes/.local/lib/python3.8/site-packages/IPython/core/ultratb.py\", line 1118, in structured_traceback\n",
      "    return FormattedTB.structured_traceback(\n",
      "  File \"/home/osboxes/.local/lib/python3.8/site-packages/IPython/core/ultratb.py\", line 1012, in structured_traceback\n",
      "    return VerboseTB.structured_traceback(\n",
      "  File \"/home/osboxes/.local/lib/python3.8/site-packages/IPython/core/ultratb.py\", line 865, in structured_traceback\n",
      "    formatted_exception = self.format_exception_as_a_whole(etype, evalue, etb, number_of_lines_of_context,\n",
      "  File \"/home/osboxes/.local/lib/python3.8/site-packages/IPython/core/ultratb.py\", line 818, in format_exception_as_a_whole\n",
      "    frames.append(self.format_record(r))\n",
      "  File \"/home/osboxes/.local/lib/python3.8/site-packages/IPython/core/ultratb.py\", line 736, in format_record\n",
      "    result += ''.join(_format_traceback_lines(frame_info.lines, Colors, self.has_colors, lvals))\n",
      "  File \"/home/osboxes/.local/lib/python3.8/site-packages/stack_data/utils.py\", line 144, in cached_property_wrapper\n",
      "    value = obj.__dict__[self.func.__name__] = self.func(obj)\n",
      "  File \"/home/osboxes/.local/lib/python3.8/site-packages/stack_data/core.py\", line 734, in lines\n",
      "    pieces = self.included_pieces\n",
      "  File \"/home/osboxes/.local/lib/python3.8/site-packages/stack_data/utils.py\", line 144, in cached_property_wrapper\n",
      "    value = obj.__dict__[self.func.__name__] = self.func(obj)\n",
      "  File \"/home/osboxes/.local/lib/python3.8/site-packages/stack_data/core.py\", line 677, in included_pieces\n",
      "    scope_pieces = self.scope_pieces\n",
      "  File \"/home/osboxes/.local/lib/python3.8/site-packages/stack_data/utils.py\", line 144, in cached_property_wrapper\n",
      "    value = obj.__dict__[self.func.__name__] = self.func(obj)\n",
      "  File \"/home/osboxes/.local/lib/python3.8/site-packages/stack_data/core.py\", line 614, in scope_pieces\n",
      "    scope_start, scope_end = self.source.line_range(self.scope)\n",
      "  File \"/home/osboxes/.local/lib/python3.8/site-packages/stack_data/core.py\", line 178, in line_range\n",
      "    return line_range(self.asttext(), node)\n",
      "  File \"/home/osboxes/.local/lib/python3.8/site-packages/executing/executing.py\", line 428, in asttext\n",
      "    self._asttext = ASTText(self.text, tree=self.tree, filename=self.filename)\n",
      "  File \"/home/osboxes/.local/lib/python3.8/site-packages/asttokens/asttokens.py\", line 307, in __init__\n",
      "    super(ASTText, self).__init__(source_text, filename)\n",
      "  File \"/home/osboxes/.local/lib/python3.8/site-packages/asttokens/asttokens.py\", line 44, in __init__\n",
      "    source_text = six.ensure_text(source_text)\n",
      "AttributeError: module 'six' has no attribute 'ensure_text'\n"
     ]
    }
   ],
   "source": [
    "tf.enable_eager_execution()"
   ]
  },
  {
   "cell_type": "code",
   "execution_count": 6,
   "metadata": {},
   "outputs": [],
   "source": [
    "master = \"\"\n",
    "model_dir = \"./ckpt/pegasus_ckpt/cnn_dailymail\"\n",
    "use_tpu = False\n",
    "iterations_per_loop = 1000\n",
    "num_shards = 1\n",
    "param_overrides = \"vocab_filename=ckpt/pegasus_ckpt/c4.unigram.newline.10pct.96000.model,batch_size=1,beam_size=5,beam_alpha=0.6\""
   ]
  },
  {
   "cell_type": "code",
   "execution_count": 7,
   "metadata": {},
   "outputs": [
    {
     "name": "stdout",
     "output_type": "stream",
     "text": [
      "Unexpected exception formatting exception. Falling back to standard exception\n"
     ]
    },
    {
     "name": "stderr",
     "output_type": "stream",
     "text": [
      "Traceback (most recent call last):\n",
      "  File \"/home/osboxes/.local/lib/python3.8/site-packages/IPython/core/interactiveshell.py\", line 3460, in run_code\n",
      "    exec(code_obj, self.user_global_ns, self.user_ns)\n",
      "  File \"/tmp/ipykernel_5449/4269772339.py\", line 3, in <module>\n",
      "    checkpoint_path = tf.train.latest_checkpoint(checkpoint_path )\n",
      "NameError: name 'tf' is not defined\n",
      "\n",
      "During handling of the above exception, another exception occurred:\n",
      "\n",
      "Traceback (most recent call last):\n",
      "  File \"/home/osboxes/.local/lib/python3.8/site-packages/IPython/core/interactiveshell.py\", line 2057, in showtraceback\n",
      "    stb = self.InteractiveTB.structured_traceback(\n",
      "  File \"/home/osboxes/.local/lib/python3.8/site-packages/IPython/core/ultratb.py\", line 1118, in structured_traceback\n",
      "    return FormattedTB.structured_traceback(\n",
      "  File \"/home/osboxes/.local/lib/python3.8/site-packages/IPython/core/ultratb.py\", line 1012, in structured_traceback\n",
      "    return VerboseTB.structured_traceback(\n",
      "  File \"/home/osboxes/.local/lib/python3.8/site-packages/IPython/core/ultratb.py\", line 865, in structured_traceback\n",
      "    formatted_exception = self.format_exception_as_a_whole(etype, evalue, etb, number_of_lines_of_context,\n",
      "  File \"/home/osboxes/.local/lib/python3.8/site-packages/IPython/core/ultratb.py\", line 818, in format_exception_as_a_whole\n",
      "    frames.append(self.format_record(r))\n",
      "  File \"/home/osboxes/.local/lib/python3.8/site-packages/IPython/core/ultratb.py\", line 736, in format_record\n",
      "    result += ''.join(_format_traceback_lines(frame_info.lines, Colors, self.has_colors, lvals))\n",
      "  File \"/home/osboxes/.local/lib/python3.8/site-packages/stack_data/utils.py\", line 144, in cached_property_wrapper\n",
      "    value = obj.__dict__[self.func.__name__] = self.func(obj)\n",
      "  File \"/home/osboxes/.local/lib/python3.8/site-packages/stack_data/core.py\", line 734, in lines\n",
      "    pieces = self.included_pieces\n",
      "  File \"/home/osboxes/.local/lib/python3.8/site-packages/stack_data/utils.py\", line 144, in cached_property_wrapper\n",
      "    value = obj.__dict__[self.func.__name__] = self.func(obj)\n",
      "  File \"/home/osboxes/.local/lib/python3.8/site-packages/stack_data/core.py\", line 677, in included_pieces\n",
      "    scope_pieces = self.scope_pieces\n",
      "  File \"/home/osboxes/.local/lib/python3.8/site-packages/stack_data/utils.py\", line 144, in cached_property_wrapper\n",
      "    value = obj.__dict__[self.func.__name__] = self.func(obj)\n",
      "  File \"/home/osboxes/.local/lib/python3.8/site-packages/stack_data/core.py\", line 614, in scope_pieces\n",
      "    scope_start, scope_end = self.source.line_range(self.scope)\n",
      "  File \"/home/osboxes/.local/lib/python3.8/site-packages/stack_data/core.py\", line 178, in line_range\n",
      "    return line_range(self.asttext(), node)\n",
      "  File \"/home/osboxes/.local/lib/python3.8/site-packages/executing/executing.py\", line 428, in asttext\n",
      "    self._asttext = ASTText(self.text, tree=self.tree, filename=self.filename)\n",
      "  File \"/home/osboxes/.local/lib/python3.8/site-packages/asttokens/asttokens.py\", line 307, in __init__\n",
      "    super(ASTText, self).__init__(source_text, filename)\n",
      "  File \"/home/osboxes/.local/lib/python3.8/site-packages/asttokens/asttokens.py\", line 44, in __init__\n",
      "    source_text = six.ensure_text(source_text)\n",
      "AttributeError: module 'six' has no attribute 'ensure_text'\n"
     ]
    }
   ],
   "source": [
    "eval_dir = os.path.dirname(model_dir)\n",
    "checkpoint_path = model_dir\n",
    "checkpoint_path = tf.train.latest_checkpoint(checkpoint_path )\n",
    "params = registry.get_params('cnn_dailymail_transformer')(param_overrides)\n",
    "pattern = params.dev_pattern\n",
    "input_fn = infeed.get_input_fn(params.parser, pattern,\n",
    "                                     tf.estimator.ModeKeys.PREDICT)\n",
    "parser, shapes = params.parser(mode=tf.estimator.ModeKeys.PREDICT)"
   ]
  },
  {
   "cell_type": "code",
   "execution_count": 8,
   "metadata": {},
   "outputs": [
    {
     "name": "stdout",
     "output_type": "stream",
     "text": [
      "Unexpected exception formatting exception. Falling back to standard exception\n"
     ]
    },
    {
     "name": "stderr",
     "output_type": "stream",
     "text": [
      "Traceback (most recent call last):\n",
      "  File \"/home/osboxes/.local/lib/python3.8/site-packages/IPython/core/interactiveshell.py\", line 3460, in run_code\n",
      "    exec(code_obj, self.user_global_ns, self.user_ns)\n",
      "  File \"/tmp/ipykernel_5449/77618992.py\", line 1, in <module>\n",
      "    estimator = estimator_utils.create_estimator(master,\n",
      "NameError: name 'estimator_utils' is not defined\n",
      "\n",
      "During handling of the above exception, another exception occurred:\n",
      "\n",
      "Traceback (most recent call last):\n",
      "  File \"/home/osboxes/.local/lib/python3.8/site-packages/IPython/core/interactiveshell.py\", line 2057, in showtraceback\n",
      "    stb = self.InteractiveTB.structured_traceback(\n",
      "  File \"/home/osboxes/.local/lib/python3.8/site-packages/IPython/core/ultratb.py\", line 1118, in structured_traceback\n",
      "    return FormattedTB.structured_traceback(\n",
      "  File \"/home/osboxes/.local/lib/python3.8/site-packages/IPython/core/ultratb.py\", line 1012, in structured_traceback\n",
      "    return VerboseTB.structured_traceback(\n",
      "  File \"/home/osboxes/.local/lib/python3.8/site-packages/IPython/core/ultratb.py\", line 865, in structured_traceback\n",
      "    formatted_exception = self.format_exception_as_a_whole(etype, evalue, etb, number_of_lines_of_context,\n",
      "  File \"/home/osboxes/.local/lib/python3.8/site-packages/IPython/core/ultratb.py\", line 818, in format_exception_as_a_whole\n",
      "    frames.append(self.format_record(r))\n",
      "  File \"/home/osboxes/.local/lib/python3.8/site-packages/IPython/core/ultratb.py\", line 736, in format_record\n",
      "    result += ''.join(_format_traceback_lines(frame_info.lines, Colors, self.has_colors, lvals))\n",
      "  File \"/home/osboxes/.local/lib/python3.8/site-packages/stack_data/utils.py\", line 144, in cached_property_wrapper\n",
      "    value = obj.__dict__[self.func.__name__] = self.func(obj)\n",
      "  File \"/home/osboxes/.local/lib/python3.8/site-packages/stack_data/core.py\", line 734, in lines\n",
      "    pieces = self.included_pieces\n",
      "  File \"/home/osboxes/.local/lib/python3.8/site-packages/stack_data/utils.py\", line 144, in cached_property_wrapper\n",
      "    value = obj.__dict__[self.func.__name__] = self.func(obj)\n",
      "  File \"/home/osboxes/.local/lib/python3.8/site-packages/stack_data/core.py\", line 677, in included_pieces\n",
      "    scope_pieces = self.scope_pieces\n",
      "  File \"/home/osboxes/.local/lib/python3.8/site-packages/stack_data/utils.py\", line 144, in cached_property_wrapper\n",
      "    value = obj.__dict__[self.func.__name__] = self.func(obj)\n",
      "  File \"/home/osboxes/.local/lib/python3.8/site-packages/stack_data/core.py\", line 614, in scope_pieces\n",
      "    scope_start, scope_end = self.source.line_range(self.scope)\n",
      "  File \"/home/osboxes/.local/lib/python3.8/site-packages/stack_data/core.py\", line 178, in line_range\n",
      "    return line_range(self.asttext(), node)\n",
      "  File \"/home/osboxes/.local/lib/python3.8/site-packages/executing/executing.py\", line 428, in asttext\n",
      "    self._asttext = ASTText(self.text, tree=self.tree, filename=self.filename)\n",
      "  File \"/home/osboxes/.local/lib/python3.8/site-packages/asttokens/asttokens.py\", line 307, in __init__\n",
      "    super(ASTText, self).__init__(source_text, filename)\n",
      "  File \"/home/osboxes/.local/lib/python3.8/site-packages/asttokens/asttokens.py\", line 44, in __init__\n",
      "    source_text = six.ensure_text(source_text)\n",
      "AttributeError: module 'six' has no attribute 'ensure_text'\n"
     ]
    }
   ],
   "source": [
    "estimator = estimator_utils.create_estimator(master, \n",
    "                                             model_dir,\n",
    "                                             use_tpu,\n",
    "                                             iterations_per_loop,\n",
    "                                             num_shards, params)\n",
    "\n",
    "_SPM_VOCAB = 'ckpt/pegasus_ckpt/c4.unigram.newline.10pct.96000.model'\n",
    "encoder = public_parsing_ops.create_text_encoder(\"sentencepiece\", \n",
    "                                                     _SPM_VOCAB)"
   ]
  },
  {
   "cell_type": "code",
   "execution_count": 9,
   "metadata": {},
   "outputs": [],
   "source": [
    "input_text = \"Eighteen sailors were injured after an explosion and fire on board a ship at the US Naval Base in San Diego, US Navy officials said.The sailors on the USS Bonhomme Richard had 'minor injuries' from the fire and were taken to a hospital, Lt. Cmdr. Patricia Kreuzberger told CNN.\"\n",
    "target = \"18 sailors injured after an explosion and fire on a naval ship in San Diego\"\n",
    "\n",
    "\n",
    "def input_function(params):\n",
    "    dataset = tf.data.Dataset.from_tensor_slices({\"inputs\":[input_text, input_text],\"targets\":[target, target]}).map(parser)\n",
    "    dataset = dataset.unbatch()\n",
    "    dataset = dataset.padded_batch(\n",
    "        params[\"batch_size\"],\n",
    "        padded_shapes=shapes,\n",
    "        drop_remainder=True)\n",
    "    return dataset"
   ]
  },
  {
   "cell_type": "code",
   "execution_count": 10,
   "metadata": {},
   "outputs": [
    {
     "name": "stdout",
     "output_type": "stream",
     "text": [
      "Unexpected exception formatting exception. Falling back to standard exception\n"
     ]
    },
    {
     "name": "stderr",
     "output_type": "stream",
     "text": [
      "Traceback (most recent call last):\n",
      "  File \"/home/osboxes/.local/lib/python3.8/site-packages/IPython/core/interactiveshell.py\", line 3460, in run_code\n",
      "    exec(code_obj, self.user_global_ns, self.user_ns)\n",
      "  File \"/tmp/ipykernel_5449/2922353227.py\", line 1, in <module>\n",
      "    predictions = estimator.predict(\n",
      "NameError: name 'estimator' is not defined\n",
      "\n",
      "During handling of the above exception, another exception occurred:\n",
      "\n",
      "Traceback (most recent call last):\n",
      "  File \"/home/osboxes/.local/lib/python3.8/site-packages/IPython/core/interactiveshell.py\", line 2057, in showtraceback\n",
      "    stb = self.InteractiveTB.structured_traceback(\n",
      "  File \"/home/osboxes/.local/lib/python3.8/site-packages/IPython/core/ultratb.py\", line 1118, in structured_traceback\n",
      "    return FormattedTB.structured_traceback(\n",
      "  File \"/home/osboxes/.local/lib/python3.8/site-packages/IPython/core/ultratb.py\", line 1012, in structured_traceback\n",
      "    return VerboseTB.structured_traceback(\n",
      "  File \"/home/osboxes/.local/lib/python3.8/site-packages/IPython/core/ultratb.py\", line 865, in structured_traceback\n",
      "    formatted_exception = self.format_exception_as_a_whole(etype, evalue, etb, number_of_lines_of_context,\n",
      "  File \"/home/osboxes/.local/lib/python3.8/site-packages/IPython/core/ultratb.py\", line 818, in format_exception_as_a_whole\n",
      "    frames.append(self.format_record(r))\n",
      "  File \"/home/osboxes/.local/lib/python3.8/site-packages/IPython/core/ultratb.py\", line 736, in format_record\n",
      "    result += ''.join(_format_traceback_lines(frame_info.lines, Colors, self.has_colors, lvals))\n",
      "  File \"/home/osboxes/.local/lib/python3.8/site-packages/stack_data/utils.py\", line 144, in cached_property_wrapper\n",
      "    value = obj.__dict__[self.func.__name__] = self.func(obj)\n",
      "  File \"/home/osboxes/.local/lib/python3.8/site-packages/stack_data/core.py\", line 734, in lines\n",
      "    pieces = self.included_pieces\n",
      "  File \"/home/osboxes/.local/lib/python3.8/site-packages/stack_data/utils.py\", line 144, in cached_property_wrapper\n",
      "    value = obj.__dict__[self.func.__name__] = self.func(obj)\n",
      "  File \"/home/osboxes/.local/lib/python3.8/site-packages/stack_data/core.py\", line 677, in included_pieces\n",
      "    scope_pieces = self.scope_pieces\n",
      "  File \"/home/osboxes/.local/lib/python3.8/site-packages/stack_data/utils.py\", line 144, in cached_property_wrapper\n",
      "    value = obj.__dict__[self.func.__name__] = self.func(obj)\n",
      "  File \"/home/osboxes/.local/lib/python3.8/site-packages/stack_data/core.py\", line 614, in scope_pieces\n",
      "    scope_start, scope_end = self.source.line_range(self.scope)\n",
      "  File \"/home/osboxes/.local/lib/python3.8/site-packages/stack_data/core.py\", line 178, in line_range\n",
      "    return line_range(self.asttext(), node)\n",
      "  File \"/home/osboxes/.local/lib/python3.8/site-packages/executing/executing.py\", line 428, in asttext\n",
      "    self._asttext = ASTText(self.text, tree=self.tree, filename=self.filename)\n",
      "  File \"/home/osboxes/.local/lib/python3.8/site-packages/asttokens/asttokens.py\", line 307, in __init__\n",
      "    super(ASTText, self).__init__(source_text, filename)\n",
      "  File \"/home/osboxes/.local/lib/python3.8/site-packages/asttokens/asttokens.py\", line 44, in __init__\n",
      "    source_text = six.ensure_text(source_text)\n",
      "AttributeError: module 'six' has no attribute 'ensure_text'\n"
     ]
    }
   ],
   "source": [
    "predictions = estimator.predict(\n",
    "          input_fn=input_function, checkpoint_path=checkpoint_path)\n",
    "\n",
    "for i in predictions:\n",
    "    print(text_eval.ids2str(encoder, i['outputs'], None))\n",
    "    break\n",
    "\n",
    "# Ouput - \"The USS Bonhomme Richard had 'minor injuries' from the fire and were taken to a hospital .\""
   ]
  }
 ],
 "metadata": {
  "kernelspec": {
   "display_name": "Python 3.8.10 64-bit",
   "language": "python",
   "name": "python3"
  },
  "language_info": {
   "codemirror_mode": {
    "name": "ipython",
    "version": 3
   },
   "file_extension": ".py",
   "mimetype": "text/x-python",
   "name": "python",
   "nbconvert_exporter": "python",
   "pygments_lexer": "ipython3",
   "version": "3.8.10"
  },
  "orig_nbformat": 4,
  "vscode": {
   "interpreter": {
    "hash": "916dbcbb3f70747c44a77c7bcd40155683ae19c65e1c03b4aa3499c5328201f1"
   }
  }
 },
 "nbformat": 4,
 "nbformat_minor": 2
}
